<?xml version="1.0" ?>
<!-- =================================================================================== -->
<!-- |    This document was autogenerated by xacro from fact_robot.xacro               | -->
<!-- |    EDITING THIS FILE BY HAND IS NOT RECOMMENDED                                 | -->
<!-- =================================================================================== -->
<robot name="fact_robot">
  <link name="robot_base">
    <visual>
      <origin rpy="0 0 0" xyz="0 0 0.0"/>
      <geometry>
        <box size="0.5 0.5 0.18"/>
      </geometry>
      <material name="Cyan">
        <color rgba="0 0.0 1.0 1.0"/>
      </material>
    </visual>
    <collision>
      <origin rpy="0 0 0" xyz="0 0 0"/>
      <geometry>
        <box size="0.5 0.5 0.18"/>
      </geometry>
    </collision>
    <inertial>
      <inertia ixx="0.047066666666666666" ixy="0" ixz="0" iyy="0.047066666666666666" iyz="0" izz="0.08333333333333333"/>
      <mass value="0.002"/>
    </inertial>
  </link>
  
  <link name="controleur">
    <inertial>
      <inertia ixx="0.6675" ixy="0" ixz="0" iyy="0.24083333333333334" iyz="0" izz="0.5333333333333333"/>
      <mass value="0.001"/>
    </inertial>
    <visual>
      <origin rpy="0 0 0" xyz="-0.4 0.0 0.75"/>
      <geometry>
        <box size="0.8 2.4 1.5"/>
      </geometry>
      <material name="gray">
        <color rgba="0.5 0.5 0.5 1.0"/>
      </material>
    </visual>
    <collision>
      <origin rpy="0 0 0" xyz="-0.4 0.0 0.75"/>
      <geometry>
        <box size="0.8 2.4 1.5"/>
      </geometry>
    </collision>
  </link>
  <link name="table">
    <inertial>
      <inertia ixx="0.14101866666666665" ixy="0" ixz="0" iyy="0.46101866666666674" iyz="0" izz="0.48666666666666675"/>
      <mass value="0.001"/>
    </inertial>
    <visual>
      <origin rpy="0 0 0" xyz="1.1 0.5 0.4115"/>
      <geometry>
        <box size="2.2 1.0 0.823"/>
      </geometry>
      <material name="wood">
        <color rgba="1 0.9 0.8 1.0"/>
      </material>
    </visual>
    <collision>
      <origin rpy="0 0 0" xyz="1.1 0.5 0.4115"/>
      <geometry>
        <box size="2.2 1.0 0.823"/>
      </geometry>
    </collision>
  </link>
  <!-- <link name="arm_1">
    <visual>
      <origin rpy="0 0 0" xyz="0 0 0"/>
      <geometry>
        <box size="0.04 0.08 0.86"/>
      </geometry>
      <material name="Cyan">
        <color rgba="0 1.0 1.0 1.0"/>
      </material>
    </visual>
    <collision>
      <origin rpy="0 0 0" xyz="0 0 0"/>
      <geometry>
        <box size="0.04 0.08 0.86"/>
      </geometry>
    </collision>
    <inertial>
      <inertia ixx="0.031083333333333327" ixy="0" ixz="0" iyy="0.030883333333333332" iyz="0" izz="0.0003333333333333333"/>
      <mass value="0.0005"/>
    </inertial>
  </link>
  <link name="arm_2">
    <visual>
      <origin rpy="1.5708 0 0" xyz="0 0 -0.175"/>
      <geometry>
        <box size="0.04 0.04 0.35"/>
      </geometry>
      <material name="Cyan">
        <color rgba="0 1.0 1.0 1.0"/>
      </material>
    </visual>
    <collision>
      <origin rpy="1.5708 0 0" xyz="0 0 -0.175"/>
      <geometry>
        <box size="0.04 0.04 0.35"/>
      </geometry>
    </collision>
    <inertial>
      <inertia ixx="0.002068333333333333" ixy="0" ixz="0" iyy="0.002068333333333333" iyz="0" izz="5.333333333333334e-05"/>
      <mass value="0.0002"/>
    </inertial>
  </link> -->
  <link name="box_contact">
    <visual>
      <origin rpy="0 0 0" xyz="0.0 0.0 0"/>
      <geometry>
        <box size="0.05 0.01 0.10"/>
      </geometry>
      <material name="Cyan">
        <color rgba="0 1.0 1.0 1.0"/>
      </material>
    </visual>
    <collision name="box_collision">
      <origin rpy="0 0 0" xyz="0.0 0.0 0"/>
      <geometry>
        <box size="0.03 0.01 0.10"/>
      </geometry>
    </collision>
    <inertial>
      <inertia ixx="0.002068333333333333" ixy="0" ixz="0" iyy="0.002068333333333333" iyz="0" izz="5.333333333333334e-05"/>
      <mass value="0.0002"/>
    </inertial>
  </link>
  <gazebo reference="box_contact">
    <sensor name="gripper_contact_sensor" type="contact">
      <always_on>1</always_on>
      <update_rate>10.0</update_rate>
      <contact>
        <collision>box_collision_collision</collision>
      </contact>
      <plugin filename="libgazebo_ros_bumper.so" name="box_bumper">
        <bumperTopicName>box_bumper</bumperTopicName>
        <frameName>box_contact</frameName>
      </plugin>
    </sensor>
  </gazebo>
  <link name="piece">
    <visual>
      <origin rpy="-1.5707896 0 0" xyz="0.055 0.14 0"/>
      <geometry>
        <mesh filename="file:///$(find cell_envir)/urdf/piece_description/Part1V3.stl" scale="0.001 0.001 0.001"/>
      </geometry>
      <material name="Cyan">
        <color rgba="0 0.0 1.0 1.0"/>
      </material>
    </visual>
    <inertial>
      <inertia ixx="0.002833333333333334" ixy="0" ixz="0" iyy="0.002833333333333334" iyz="0" izz="0.005333333333333335"/>
      <mass value="0.0002"/>
    </inertial>
  </link>
  <link name="frame1">
    </link>
  <joint name="joint_piece_frame1" type="fixed">
    <origin rpy="0.0 0.0 0.0" xyz="0.15 0.027 0.0"/>
    <parent link="piece"/>
    <child link="frame1"/>
  </joint>
  <link name="frame2">
    </link>
  <joint name="joint_piece_frame2" type="fixed">
    <origin rpy="0.0 0.0 0.0" xyz="-0.15 0.027 0.0"/>
    <parent link="piece"/>
    <child link="frame2"/>
  </joint>
  <link name="frame3">
    </link>
  <joint name="joint_piece_frame3" type="fixed">
    <origin rpy="0.0 0.0 0.0" xyz="0.0 -0.184 0.0"/>
    <parent link="piece"/>
    <child link="frame3"/>
  </joint>
  <link name="frame4">
    </link>
  <joint name="joint_piece_frame4" type="fixed">
    <origin rpy="0.0 0.0 0.0" xyz="0.0 0.1567 0.0"/>
    <parent link="piece"/>
    <child link="frame4"/>
  </joint>
  <joint name="joint_base_world" type="fixed">
    <origin rpy="0.0 0.0 0.0" xyz="0.0 0.0 0.09"/>
    <parent link="world"/>
    <child link="robot_base"/>
  </joint>
  <joint name="joint_controleur" type="fixed">
    <origin rpy="0.0 0.0 0.0" xyz="-1.2 0.1 0.0"/>
    <parent link="world"/>
    <child link="controleur"/>
  </joint>
  <joint name="joint_table" type="fixed">
    <origin rpy="0.0 0.0 0.0" xyz="-0.430 1.4 0"/>
    <parent link="world"/>
    <child link="table"/>
  </joint>
  
  <!-- <joint name="joint_arm1" type="fixed">
    <origin rpy="0.0 0.0 0.0" xyz="1.075718 -0.717824 0.43"/>
    <parent link="world"/>
    <child link="arm_1"/>
  </joint>
  <joint name="joint_arm1_arm2" type="fixed">
    <origin rpy="0.0 0.0 0.0" xyz="0.0 0.135 0.62"/>
    <parent link="arm_1"/>
    <child link="arm_2"/>
  </joint> -->
  <joint name="joint_piece_world" type="fixed">
    <origin rpy="0.0 0.0 0.0" xyz="1.075718 0.0 0.86"/>
    <parent link="world"/>
    <child link="piece"/>
  </joint>
  <joint name="joint_contactObject_world" type="fixed">
    <origin rpy="0.0 0.0 0.0" xyz="1.075718 0.35 0.96"/>
    <parent link="world"/>
    <child link="box_contact"/>
  </joint>
  <material name="Ensenso/Blue">
    <color rgba="0.1 0.1 1.0 1.0"/>
  </material>
  <material name="Ensenso/Black">
    <color rgba="0.0 0.0 0.0 1.0"/>
  </material>
  <!-- Define the links -->
  <!-- <link name="custom_gripper_base">
    <visual>
      <geometry>
        <box size="0.2 0.02 0.02"/>
      </geometry>
      <origin rpy="0 0 0" xyz="0 0 0"/>
      <material name="grey">
        <color rgba="0.5 0.5 0.5 1"/>
      </material>
    </visual>
    <collision>
      <geometry>
        <box size="0.2 0.02 0.02"/>
      </geometry>
      <origin rpy="0 0 0" xyz="0 0 0"/>
    </collision>
    <inertial>
      <inertia ixx="1.3333333333333335e-05" ixy="0" ixz="0" iyy="0.0006733333333333335" iyz="0" izz="0.0006733333333333335"/>
      <mass value="0.2"/>
    </inertial>
  </link> -->
  <!--
  <xacro:finger name="left_finger" x_pos="-0.05" size_x="0.1" size_y="0.02" size_z="0.02"/>
  <xacro:finger name="right_finger" x_pos="0.05" size_x="0.1" size_y="0.02" size_z="0.02"/>

  <xacro:prismatic_joint name="left_finger_joint" parent="custom_gripper_base" child="left_finger" rotation="-1.570796" x_pos="-0.1" y_pos="0.01" lower_lim="0.01" upper_lim="0.09"/>
  <xacro:prismatic_joint name="right_finger_joint" parent="custom_gripper_base" child="right_finger" rotation="1.570796" x_pos="0.1" y_pos="0.01" lower_lim="0.01" upper_lim="0.09"/>
-->
  <joint name="camera_optical_joint" type="fixed">
    <parent link="link_6_t"/>
    <child link="camera_link_optical"/>
    <origin rpy="1.5708 3.14159 1.5708" xyz="0.26 -0.11 0.155"/>
  </joint>
  <joint name="camera_joint" type="fixed">
    <parent link="camera_link_optical"/>
    <child link="camera_link"/>
    <origin rpy="0 -1.5708 1.5708" xyz="0.0 0.0 0.0"/>
  </joint>
  <link name="camera_link_optical"/>
  <link name="camera_link">
    <origin rpy="0 0 0" xyz="0 0 0"/>
    <visual>
      <geometry>
        <box size="0.01 0.01 0.01"/>
      </geometry>
      <material name="red"/>
    </visual>
    <collision>
      <origin rpy="0 0 0" xyz="0 0 0"/>
      <geometry>
        <box size="0.01 0.01 0.01"/>
      </geometry>
    </collision>
    <inertial>
      <inertia ixx="3.333333333333334e-07" ixy="0" ixz="0" iyy="3.333333333333334e-07" iyz="0" izz="3.333333333333334e-07"/>
      <mass value="2e-05"/>
    </inertial>
  </link>
  <gazebo reference="camera_link">
    <material>Gazebo/Red</material>
    <sensor name="my_depth_camera" type="depth">
      <always_on>true</always_on>
      <visualize>false</visualize>
      <update_rate>5</update_rate>
      <camera name="camera">
        <horizontal_fov>1.02974</horizontal_fov>
        <image>
          <width>640</width>
          <height>480</height>
          <format>R8G8B8</format>
        </image>
        <clip>
          <near>0.02</near>
          <far>1</far>
        </clip>
        <noise>
          <type>gaussian</type>
          <!-- Noise is sampled independently per pixel on each frame.
                            That pixel's noise value is added to each of its color
                            channels, which at that point lie in the range [0,1]. -->
          <mean>0.0</mean>
          <stddev>0.007</stddev>
        </noise>
      </camera>
      <plugin filename="libgazebo_ros_camera.so" name="depth_camera_controller">
        <camera_name>my_depth_camera</camera_name>
        <frame_name> camera_link_optical</frame_name>
        <hack_baseline>0</hack_baseline>
        <min_depth>0.01</min_depth>
        <min_depth>0.5</min_depth>
      </plugin>
    </sensor>
  </gazebo>
  <!-- link list -->
  <link name="base_link">
    <visual>
      <geometry>
        <mesh filename="file:///$(find cell_envir)/urdf/motoman_mh12_support/meshes/visual/mh12_base_link.stl"/>
      </geometry>
      <material name="">
        <color rgba="0.12941176470588237 0.14901960784313725 0.7490196078431373 1.0"/>
      </material>
    </visual>
    <collision>
      <geometry>
        <mesh filename="file:///$(find cell_envir)/urdf/motoman_mh12_support/meshes/collision/mh12_base_link.stl"/>
      </geometry>
    </collision>
    <inertial>
      <inertia ixx="0.6499999999999999" ixy="0" ixz="0" iyy="0.6499999999999999" iyz="0" izz="1.2249999999999999"/>
      <mass value="0.005"/>
    </inertial>
  </link>
  <link name="link_1_s">
    <visual>
      <geometry>
        <mesh filename="file:///$(find cell_envir)/urdf/motoman_mh12_support/meshes/visual/mh12_link_1_s.stl"/>
      </geometry>
      <material name="">
        <color rgba="0.12941176470588237 0.14901960784313725 0.7490196078431373 1.0"/>
      </material>
    </visual>
    <collision>
      <geometry>
        <mesh filename="file:///$(find cell_envir)/urdf/motoman_mh12_support/meshes/collision/mh12_link_1_s.stl"/>
      </geometry>
    </collision>
    <inertial>
      <inertia ixx="0.4624999999999999" ixy="0" ixz="0" iyy="0.4624999999999999" iyz="0" izz="0.625"/>
      <mass value="0.005"/>
    </inertial>
  </link>
  <link name="link_2_l">
    <visual>
      <geometry>
        <mesh filename="file:///$(find cell_envir)/urdf/motoman_mh12_support/meshes/visual/mh12_link_2_l.stl"/>
      </geometry>
      <material name="">
        <color rgba="0.12941176470588237 0.14901960784313725 0.7490196078431373 1.0"/>
      </material>
    </visual>
    <collision>
      <geometry>
        <mesh filename="file:///$(find cell_envir)/urdf/motoman_mh12_support/meshes/collision/mh12_link_2_l.stl"/>
      </geometry>
    </collision>
    <inertial>
      <inertia ixx="0.7041666666666669" ixy="0" ixz="0" iyy="0.7041666666666669" iyz="0" izz="0.4"/>
      <mass value="0.005"/>
    </inertial>
  </link>
  <link name="link_3_u">
    <visual>
      <geometry>
        <mesh filename="file:///$(find cell_envir)/urdf/motoman_mh12_support/meshes/visual/mh12_link_3_u.stl"/>
      </geometry>
      <material name="">
        <color rgba="0.12941176470588237 0.14901960784313725 0.7490196078431373 1.0"/>
      </material>
    </visual>
    <collision>
      <geometry>
        <mesh filename="file:///$(find cell_envir)/urdf/motoman_mh12_support/meshes/collision/mh12_link_3_u.stl"/>
      </geometry>
    </collision>
    <inertial>
      <inertia ixx="0.5541666666666666" ixy="0" ixz="0" iyy="0.5541666666666666" iyz="0" izz="0.8999999999999999"/>
      <mass value="0.005"/>
    </inertial>
  </link>
  <link name="link_4_r">
    <visual>
      <geometry>
        <mesh filename="file:///$(find cell_envir)/urdf/motoman_mh12_support/meshes/visual/mh12_link_4_r.stl"/>
      </geometry>
      <material name="">
        <color rgba="0.12941176470588237 0.14901960784313725 0.7490196078431373 1.0"/>
      </material>
    </visual>
    <collision>
      <geometry>
        <mesh filename="file:///$(find cell_envir)/urdf/motoman_mh12_support/meshes/collision/mh12_link_4_r.stl"/>
      </geometry>
    </collision>
    <inertial>
      <inertia ixx="0.16000000000000003" ixy="0" ixz="0" iyy="0.16000000000000003" iyz="0" izz="0.24000000000000005"/>
      <mass value="0.003"/>
    </inertial>
  </link>
  <link name="link_5_b">
    <visual>
      <geometry>
        <mesh filename="file:///$(find cell_envir)/urdf/motoman_mh12_support/meshes/visual/mh12_link_5_b.stl"/>
      </geometry>
      <material name="">
        <color rgba="0.12941176470588237 0.14901960784313725 0.7490196078431373 1.0"/>
      </material>
    </visual>
    <collision>
      <geometry>
        <mesh filename="file:///$(find cell_envir)/urdf/motoman_mh12_support/meshes/collision/mh12_link_5_b.stl"/>
      </geometry>
    </collision>
    <inertial>
      <inertia ixx="0.05166666666666666" ixy="0" ixz="0" iyy="0.05166666666666666" iyz="0" izz="0.09"/>
      <mass value="0.002"/>
    </inertial>
  </link>
  <link name="link_6_t">
    <visual>
      <geometry>
        <mesh filename="file:///$(find cell_envir)/urdf/motoman_mh12_support/meshes/visual/mh12_link_6_t.stl"/>
      </geometry>
      <material name="">
        <color rgba="0.12941176470588237 0.14901960784313725 0.7490196078431373 1.0"/>
      </material>
    </visual>
    <collision>
      <geometry>
        <mesh filename="file:///$(find cell_envir)/urdf/motoman_mh12_support/meshes/collision/mh12_link_6_t.stl"/>
      </geometry>
    </collision>
    <inertial>
      <inertia ixx="0.06499999999999999" ixy="0" ixz="0" iyy="0.06499999999999999" iyz="0" izz="0.12249999999999998"/>
      <mass value="0.0005"/>
    </inertial>
  </link>
  <link name="tool0"/>
  <!-- end of link list -->
  <!-- joint list -->
  <joint name="joint_1_s" type="revolute">
    <parent link="base_link"/>
    <child link="link_1_s"/>
    <origin rpy="0 0 0" xyz="0 0 0.450"/>
    <axis xyz="0 0 1"/>
    <limit effort="648.27" lower="-2.9670" upper="2.9670" velocity="3.8397"/>
  </joint>
  <joint name="joint_2_l" type="revolute">
    <parent link="link_1_s"/>
    <child link="link_2_l"/>
    <origin rpy="0 0 0" xyz="0.155 0 0"/>
    <axis xyz="0 1 0"/>
    <limit effort="874.65" lower="-1.5708" upper="2.7052" velocity="3.4906"/>
  </joint>
  <joint name="joint_3_u" type="revolute">
    <parent link="link_2_l"/>
    <child link="link_3_u"/>
    <origin rpy="0 0 0" xyz="0 0 0.614"/>
    <axis xyz="0 -1 0"/>
    <limit effort="257.25" lower="-1.4835" upper="2.6179" velocity="3.8397"/>
  </joint>
  <joint name="joint_4_r" type="revolute">
    <parent link="link_3_u"/>
    <child link="link_4_r"/>
    <origin rpy="0 0 0" xyz="0.640 0 0.200"/>
    <axis xyz="-1 0 0"/>
    <limit effort="74.97" lower="-3.1415" upper="3.1415" velocity="7.1558"/>
  </joint>
  <joint name="joint_5_b" type="revolute">
    <parent link="link_4_r"/>
    <child link="link_5_b"/>
    <origin rpy="0 0 0" xyz="0 0 0"/>
    <axis xyz="0 -1 0"/>
    <limit effort="44.69" lower="-2.3562" upper="2.3562" velocity="7.1558"/>
  </joint>
  <joint name="joint_6_t" type="revolute">
    <parent link="link_5_b"/>
    <child link="link_6_t"/>
    <origin rpy="0 0 0" xyz="0 0 0"/>
    <axis xyz="-1 0 0"/>
    <limit effort="14.80" lower="-6.2832" upper="6.2832" velocity="10.6465"/>
  </joint>
  <joint name="joint_6_t-tool0" type="fixed">
    <origin rpy="3.1415926 -1.570796 0" xyz="0.100 0 0"/>
    <parent link="link_6_t"/>
    <child link="tool0"/>
  </joint>
  <!-- end of joint list -->
  <!-- ROS base_link to Robot Manufacturer World Coordinates transform 
        <link name="${prefix}base" />
        <joint name="${prefix}base_link-base" type="fixed">
            <origin xyz="0 0 0.450" rpy="0 0 0"/>
            <parent link="${prefix}base_link"/>
            <child link="${prefix}base"/>
        </joint>
        -->
  <link name="my_camera">
    <visual>
      <origin rpy="0 0 0" xyz="0 0 0"/>
      <geometry>
        <mesh filename="file:///$(find cell_envir)/urdf/ensenso_description/stl_meshes/X3x-5CP-200.stl"/>
      </geometry>
      <material name="Ensenso/Blue"/>
    </visual>
    <collision>
      <origin rpy="0.0 0.0 0.0" xyz="0.0 0.0 0.058"/>
      <geometry>
        <box size="0.27349999999999997 0.096 0.16"/>
      </geometry>
    </collision>
    <inertial>
      <inertia ixx="0.0041666666666666675" ixy="0" ixz="0" iyy="0.010833333333333334" iyz="0" izz="0.008333333333333333"/>
      <mass value="0.001"/>
    </inertial>
  </link>
  <!-- Left lens -->
  <joint name="my_camera_left_lens_joint" type="fixed">
    <parent link="my_camera"/>
    <child link="my_camera_left_lens_frame"/>
    <origin rpy="0 0 0" xyz="-0.113 0.0 0.063"/>
  </joint>
  <link name="my_camera_left_lens_frame"/>
  <link name="world">
  </link>
  <link name="gripper">
    <visual>
      <origin rpy="0 0 0" xyz="0 0 0"/>
      <geometry>
        <mesh filename="file:///$(find cell_envir)/urdf/gripper_description/gripper_bi.stl" scale="0.001 0.001 0.001"/>
      </geometry>
      <material name="Cyan">
        <color rgba="0 0.0 1.0 1.0"/>
      </material>
    </visual>
    <collision name="custom_gripper_collision">
      <origin rpy="0 0 0" xyz="0 0 0"/>
      <geometry>
        <box size="0.05 0.15 0.05"/>
      </geometry>
    </collision>
    <inertial>
      <inertia ixx="0.0010416666666666667" ixy="0" ixz="0" iyy="0.00020833333333333337" iyz="0" izz="0.0010416666666666667"/>
      <mass value="0.0005"/>
    </inertial>
  </link>
  <gazebo reference="gripper">
    <sensor name="gripper_contact_sensor" type="contact">
      <always_on>true</always_on>
      <update_rate>10.0</update_rate>
      <contact>
        <collision>custom_gripper_collision_collision</collision>
      </contact>
      <plugin filename="libgazebo_ros_bumper.so" name="gripper_bumper_plugin">
        <bumperTopicName>gripper_bumper</bumperTopicName>
        <frameName>gripper</frameName>
      </plugin>
    </sensor>
  </gazebo>
  <link name="support">
    <visual>
      <origin rpy="0 0 0" xyz="0 0 0"/>
      <geometry>
        <mesh filename="file:///$(find cell_envir)/urdf/gripper_description/support2.stl" scale="0.005 0.005 0.005"/>
      </geometry>
      <material name="Cyan">
        <color rgba="0 0.0 1.0 1.0"/>
      </material>
    </visual>
    <collision>
      <origin rpy="0 0 0" xyz="0 0 0"/>
      <geometry>
        <box size="0.05 0.05 0.15"/>
      </geometry>
    </collision>
    <inertial>
      <inertia ixx="0.0010416666666666667" ixy="0" ixz="0" iyy="0.0010416666666666667" iyz="0" izz="0.00020833333333333337"/>
      <mass value="0.0005"/>
    </inertial>
  </link>
  <joint name="joint_robot_base_link" type="fixed">
    <origin rpy="0.0 0.0 0.0" xyz="0.0 0.0 0.09"/>
    <parent link="robot_base"/>
    <child link="base_link"/>
  </joint>
  <joint name="joint_tool0_camera" type="fixed">
    <origin rpy="0 0.0 -1.570789632" xyz="0.15213 0.0 0.01"/>
    <parent link="tool0"/>
    <child link="my_camera"/>
  </joint>
  <joint name="joint_tool0_support" type="fixed">
    <origin rpy="0 0.0 0" xyz="0.00 0.00 0.00"/>
    <parent link="tool0"/>
    <child link="support"/>
  </joint>
  <joint name="joint_support_gripper" type="fixed">
    <origin rpy="1.5708 0.0 1.5708" xyz="0.0 0.0 0.07"/>
    <parent link="support"/>
    <child link="gripper"/>
  </joint>
  <!-- TCP frames -->
  <link name="gripper_tcp">
  </link>
  <link name="camera_tcp">
  </link>
  <!-- <link name="pince_tcp">
  </link> -->
  <joint name="joint_gripper_tcp_gripper" type="fixed">
    <origin rpy="0 0 0" xyz="0 0.09 0"/>
    <parent link="gripper"/>
    <child link="gripper_tcp"/>
  </joint>
  <joint name="joint_camera_tcp_camera" type="fixed">
    <origin rpy="0 -1.5707963267948966 0" xyz="0 0 0.05"/>
    <parent link="my_camera_left_lens_frame"/>
    <child link="camera_tcp"/>
  </joint>
  <!-- <joint name="joint_custom_gripper_tcp_pince" type="fixed">
    <origin rpy="0 0 0" xyz="0 0.01 0"/>
    <parent link="custom_gripper_base"/>
    <child link="pince_tcp"/>
  </joint> -->
  <!-- <joint name="joint_arm_custom_gripper" type="fixed">
    <origin rpy="0 0 0" xyz="0.0 0.185 -0.17"/>
    <parent link="arm_2"/>
    <child link="custom_gripper_base"/>
  </joint> -->
  <link name="main_left_finger">
    <visual>
      <geometry>
        <box size="0.04 0.003 0.008"/>
      </geometry>
      <origin rpy="0 0 0" xyz="-0.01 0 0"/>
      <material name="grey">
        <color rgba="0.5 0.5 0.5 1"/>
      </material>
    </visual>
    <collision name="main_left_finger_collision">
      <geometry>
        <box size="0.04 0.003 0.008"/>
      </geometry>
      <origin rpy="0 0 0" xyz="-0.01 0 0"/>
    </collision>
    <inertial>
      <inertia ixx="6.6666666666666675e-06" ixy="0" ixz="0" iyy="8.666666666666668e-05" iyz="0" izz="8.666666666666668e-05"/>
      <mass value="0.0001"/>
    </inertial>
  </link>
  <gazebo reference="main_left_finger">
    <sensor name="main_left_finger_contact_sensor" type="contact">
      <always_on>true</always_on>
      <update_rate>10.0</update_rate>
      <contact>
        <collision>main_left_finger_collision_collision</collision>
      </contact>
      <plugin filename="libgazebo_ros_bumper.so" name="main_left_finger_bumper_plugin">
        <bumperTopicName>main_left_finger_bumper</bumperTopicName>
        <frameName>main_left_finger</frameName>
      </plugin>
    </sensor>
  </gazebo>
  <link name="main_right_finger">
    <visual>
      <geometry>
        <box size="0.04 0.003 0.008"/>
      </geometry>
      <origin rpy="0 0 0" xyz="0.01 0 0"/>
      <material name="grey">
        <color rgba="0.5 0.5 0.5 1"/>
      </material>
    </visual>
    <collision name="main_right_finger_collision">
      <geometry>
        <box size="0.04 0.003 0.008"/>
      </geometry>
      <origin rpy="0 0 0" xyz="0.01 0 0"/>
    </collision>
    <inertial>
      <inertia ixx="6.6666666666666675e-06" ixy="0" ixz="0" iyy="8.666666666666668e-05" iyz="0" izz="8.666666666666668e-05"/>
      <mass value="0.0001"/>
    </inertial>
  </link>
  <gazebo reference="main_right_finger">
    <sensor name="main_right_finger_contact_sensor" type="contact">
      <always_on>true</always_on>
      <update_rate>10.0</update_rate>
      <contact>
        <collision>main_right_finger_collision_collision</collision>
      </contact>
      <plugin filename="libgazebo_ros_bumper.so" name="main_right_finger_bumper_plugin">
        <bumperTopicName>main_right_finger_bumper</bumperTopicName>
        <frameName>main_right_finger</frameName>
      </plugin>
    </sensor>
  </gazebo>
  <joint name="main_left_finger_joint" type="prismatic">
    <parent link="gripper"/>
    <child link="main_left_finger"/>
    <origin rpy="0 0 -1.570796" xyz="-0.012 0.092 0"/>
    <axis xyz="0 1 0"/>
    <limit effort="100" lower="0.0" upper="0.11" velocity="0.1"/>
  </joint>
  <joint name="main_right_finger_joint" type="prismatic">
    <parent link="gripper"/>
    <child link="main_right_finger"/>
    <origin rpy="0 0 1.570796" xyz="0.012 0.092 0"/>
    <axis xyz="0 1 0"/>
    <limit effort="100" lower="0.0" upper="0.11" velocity="0.1"/>
  </joint>
</robot>
